data/output/UHR.txt
PASSIVE BUY 1860.00 @ 829.83
PASSIVE BUY 1260.00 @ 829.79
PASSIVE BUY 2940.00 @ 829.93
PASSIVE SELL 1660.00 @ 830.21
PASSIVE BUY 2620.00 @ 829.98
PASSIVE BUY 1300.00 @ 829.97
PASSIVE SELL 1100.00 @ 830.22
PASSIVE SELL 700.00 @ 830.31
PASSIVE SELL 1900.00 @ 830.11
PASSIVE BUY 2820.00 @ 830.10
AGGRESSIVE SELL 1300.00 @ 830.10
AGGRESSIVE BUY 1540.00 @ 830.11
PASSIVE BUY 1380.00 @ 829.97
AGGRESSIVE SELL 2140.00 @ 829.98
PASSIVE SELL 1300.00 @ 830.07
AGGRESSIVE BUY 1260.00 @ 830.07
PASSIVE SELL 380.00 @ 830.15
PASSIVE BUY 1620.00 @ 829.89
AGGRESSIVE BUY 2860.00 @ 830.11
CANCEL BUY 1860.00 @ 829.83
CANCEL BUY 1260.00 @ 829.79
CANCEL BUY 2940.00 @ 829.93
CANCEL BUY 2000.00 @ 829.98
CANCEL BUY -1300.00 @ 829.97
CANCEL BUY 1380.00 @ 829.97
CANCEL BUY 1620.00 @ 829.89
CANCEL BUY 2460.00 @ 830.11
PASSIVE SELL 500.00 @ 830.06
PASSIVE BUY 980.00 @ 830.05
AGGRESSIVE SELL 1700.00 @ 829.92
AGGRESSIVE BUY 2340.00 @ 829.97
AGGRESSIVE BUY 1140.00 @ 830.08
AGGRESSIVE BUY 2100.00 @ 830.19
AGGRESSIVE SELL 1860.00 @ 830.08
PASSIVE SELL 940.00 @ 830.33
PASSIVE BUY 2860.00 @ 829.99
PASSIVE SELL 2060.00 @ 830.11
PASSIVE BUY 2580.00 @ 830.02
PASSIVE SELL 1860.00 @ 830.15
AGGRESSIVE SELL 2060.00 @ 830.02
AGGRESSIVE BUY 1540.00 @ 830.11
AGGRESSIVE BUY 1460.00 @ 830.15
PASSIVE SELL 460.00 @ 830.22
AGGRESSIVE BUY 1940.00 @ 830.18
AGGRESSIVE BUY 1980.00 @ 830.22
AGGRESSIVE SELL 900.00 @ 830.18
PASSIVE SELL 1780.00 @ 830.23
AGGRESSIVE SELL 1780.00 @ 830.14
PASSIVE BUY 1500.00 @ 829.95
PASSIVE SELL 2260.00 @ 830.17
PASSIVE BUY 2740.00 @ 829.99
PASSIVE SELL 2100.00 @ 830.11
CANCEL SELL 940.00 @ 830.33
PASSIVE SELL 1260.00 @ 830.22
PASSIVE SELL 1500.00 @ 830.17
AGGRESSIVE BUY 1460.00 @ 830.11
PASSIVE BUY 2060.00 @ 829.95
PASSIVE BUY 2780.00 @ 830.01
PASSIVE SELL 1060.00 @ 830.19
CANCEL SELL 700.00 @ 830.31
PASSIVE BUY 820.00 @ 830.08
AGGRESSIVE SELL 2300.00 @ 830.05
CANCEL SELL 1780.00 @ 830.23
PASSIVE BUY 1500.00 @ 829.94
PASSIVE BUY 1860.00 @ 830.01
AGGRESSIVE SELL 2180.00 @ 830.01
PASSIVE BUY 2580.00 @ 830.04
PASSIVE SELL 1540.00 @ 830.17
AGGRESSIVE SELL 2100.00 @ 830.04
PASSIVE BUY 2860.00 @ 830.00
CANCEL BUY 1620.00 @ 829.97
CANCEL BUY -2860.00 @ 829.99
CANCEL BUY -1500.00 @ 829.95
CANCEL BUY 2740.00 @ 829.99
CANCEL BUY 2060.00 @ 829.95
CANCEL BUY -1620.00 @ 830.01
CANCEL BUY 1500.00 @ 829.94
CANCEL BUY 1860.00 @ 830.01
CANCEL BUY 480.00 @ 830.04
CANCEL BUY 2860.00 @ 830.00
AGGRESSIVE BUY 980.00 @ 830.05
PASSIVE SELL 780.00 @ 830.05
AGGRESSIVE BUY 2060.00 @ 830.10
AGGRESSIVE SELL 1340.00 @ 830.03
PASSIVE SELL 620.00 @ 830.03
PASSIVE SELL 1540.00 @ 830.04
CANCEL SELL -780.00 @ 830.22
CANCEL SELL -460.00 @ 830.22
CANCEL SELL 1260.00 @ 830.22
AGGRESSIVE BUY 2460.00 @ 830.04
PASSIVE SELL 740.00 @ 830.05
PASSIVE SELL 1060.00 @ 830.12
CANCEL SELL 1060.00 @ 830.19
PASSIVE BUY 1700.00 @ 830.01
AGGRESSIVE BUY 740.00 @ 830.05
AGGRESSIVE BUY 1780.00 @ 830.09
AGGRESSIVE BUY 1780.00 @ 830.14
AGGRESSIVE SELL 820.00 @ 830.09
PASSIVE BUY 820.00 @ 830.04
PASSIVE SELL 1900.00 @ 830.23
AGGRESSIVE BUY 1460.00 @ 830.14
AGGRESSIVE BUY 2780.00 @ 830.17
PASSIVE SELL 1180.00 @ 830.19
AGGRESSIVE BUY 820.00 @ 830.17
PASSIVE BUY 1500.00 @ 830.12
AGGRESSIVE BUY 2420.00 @ 830.19
PASSIVE BUY 2340.00 @ 830.00
AGGRESSIVE SELL 700.00 @ 830.12
PASSIVE BUY 1260.00 @ 830.04
PASSIVE BUY 1580.00 @ 830.07
AGGRESSIVE SELL 1580.00 @ 830.07
PASSIVE BUY 2780.00 @ 830.09
PASSIVE BUY 2340.00 @ 830.09
AGGRESSIVE SELL 980.00 @ 830.09
PASSIVE SELL 740.00 @ 830.18
PASSIVE SELL 580.00 @ 830.25
PASSIVE BUY 2740.00 @ 830.12
AGGRESSIVE BUY 2020.00 @ 830.23
PASSIVE SELL 2260.00 @ 830.13
PASSIVE BUY 2180.00 @ 830.12
AGGRESSIVE SELL 1580.00 @ 830.12
PASSIVE BUY 2140.00 @ 830.04
AGGRESSIVE BUY 2260.00 @ 830.13
PASSIVE BUY 2220.00 @ 830.16
CANCEL BUY 1700.00 @ 830.01
CANCEL BUY -820.00 @ 830.04
CANCEL BUY 2340.00 @ 830.00
CANCEL BUY -1260.00 @ 830.04
CANCEL BUY 1500.00 @ 830.07
CANCEL BUY -1800.00 @ 830.09
CANCEL BUY 2340.00 @ 830.09
CANCEL BUY -1160.00 @ 830.12
CANCEL BUY 2180.00 @ 830.12
CANCEL BUY 2140.00 @ 830.04
CANCEL BUY 2220.00 @ 830.16
AGGRESSIVE BUY 940.00 @ 830.23
AGGRESSIVE BUY 2580.00 @ 830.30
PASSIVE BUY 1460.00 @ 830.43
AGGRESSIVE SELL 460.00 @ 830.43
AGGRESSIVE SELL 1740.00 @ 830.41
PASSIVE SELL 500.00 @ 830.52
PASSIVE BUY 2540.00 @ 830.19
PASSIVE BUY 1300.00 @ 830.22
PASSIVE SELL 2020.00 @ 830.47
PASSIVE BUY 1660.00 @ 830.23
AGGRESSIVE BUY 900.00 @ 830.45
AGGRESSIVE BUY 1940.00 @ 830.47
AGGRESSIVE SELL 1780.00 @ 830.33
AGGRESSIVE BUY 2340.00 @ 830.44
AGGRESSIVE BUY 900.00 @ 830.61
AGGRESSIVE SELL 1780.00 @ 830.58
PASSIVE BUY 1660.00 @ 830.38
PASSIVE SELL 940.00 @ 830.52
PASSIVE SELL 1820.00 @ 830.63
PASSIVE SELL 1460.00 @ 830.48
PASSIVE BUY 2420.00 @ 830.39
CANCEL BUY 1740.00 @ 830.30
CANCEL BUY 2540.00 @ 830.19
CANCEL BUY 1300.00 @ 830.22
CANCEL BUY 1660.00 @ 830.23
CANCEL BUY 720.00 @ 830.44
CANCEL BUY 1660.00 @ 830.38
CANCEL BUY 2420.00 @ 830.39
PASSIVE SELL 1300.00 @ 830.37
PASSIVE SELL 2060.00 @ 830.48
PASSIVE SELL 1500.00 @ 830.23
AGGRESSIVE BUY 1060.00 @ 830.23
AGGRESSIVE BUY 1780.00 @ 830.48
PASSIVE SELL 1500.00 @ 830.38
AGGRESSIVE BUY 2100.00 @ 830.40
AGGRESSIVE SELL 1100.00 @ 830.39
PASSIVE SELL 1020.00 @ 830.45
PASSIVE SELL 2060.00 @ 830.48
PASSIVE SELL 380.00 @ 830.22
CANCEL SELL 1820.00 @ 830.63
PASSIVE SELL 1260.00 @ 830.20
CANCEL SELL 1460.00 @ 830.58
PASSIVE SELL 940.00 @ 830.03
CANCEL SELL 940.00 @ 830.52
AGGRESSIVE BUY 860.00 @ 830.03
PASSIVE SELL 540.00 @ 830.10
CANCEL SELL -1420.00 @ 830.48
CANCEL SELL -2060.00 @ 830.48
CANCEL SELL 2060.00 @ 830.48
PASSIVE SELL 1980.00 @ 829.90
CANCEL SELL 1020.00 @ 830.45
AGGRESSIVE BUY 900.00 @ 829.90
AGGRESSIVE BUY 740.00 @ 829.90
PASSIVE SELL 580.00 @ 829.96
CANCEL SELL 500.00 @ 830.39
PASSIVE SELL 1060.00 @ 829.75
CANCEL SELL 380.00 @ 830.22
PASSIVE SELL 1740.00 @ 829.73
CANCEL SELL 1260.00 @ 830.20
PASSIVE SELL 1820.00 @ 829.70
CANCEL SELL 540.00 @ 830.10
AGGRESSIVE BUY 2660.00 @ 829.73
PASSIVE SELL 1380.00 @ 829.84
AGGRESSIVE BUY 1860.00 @ 829.75
AGGRESSIVE BUY 1860.00 @ 829.96
AGGRESSIVE BUY 1620.00 @ 830.29
PASSIVE SELL 740.00 @ 830.45
PASSIVE SELL 1340.00 @ 830.56
PASSIVE SELL 420.00 @ 830.46
PASSIVE BUY 980.00 @ 830.20
PASSIVE BUY 2620.00 @ 830.22
PASSIVE SELL 620.00 @ 830.45
PASSIVE SELL 1340.00 @ 830.37
PASSIVE BUY 1420.00 @ 830.34
PASSIVE BUY 1220.00 @ 830.26
AGGRESSIVE BUY 2660.00 @ 830.44
AGGRESSIVE SELL 1220.00 @ 830.44
AGGRESSIVE BUY 1380.00 @ 830.46
AGGRESSIVE BUY 2780.00 @ 830.59
CANCEL BUY 1000.00 @ 830.29
CANCEL BUY 980.00 @ 830.20
CANCEL BUY 2620.00 @ 830.22
CANCEL BUY 1420.00 @ 830.34
CANCEL BUY 1220.00 @ 830.26
CANCEL BUY 100.00 @ 830.44
CANCEL BUY 1040.00 @ 830.59
PASSIVE SELL 660.00 @ 830.72
PASSIVE BUY 2820.00 @ 830.58
PASSIVE SELL 2300.00 @ 830.69
PASSIVE SELL 380.00 @ 830.79
PASSIVE SELL 1140.00 @ 830.68
PASSIVE SELL 540.00 @ 830.70
PASSIVE BUY 2260.00 @ 830.65
AGGRESSIVE SELL 2260.00 @ 830.65
PASSIVE SELL 2180.00 @ 830.70
PASSIVE BUY 1700.00 @ 830.57
PASSIVE BUY 2580.00 @ 830.53
PASSIVE SELL 1500.00 @ 830.70
PASSIVE SELL 1580.00 @ 830.71
AGGRESSIVE BUY 1140.00 @ 830.68
PASSIVE BUY 2460.00 @ 830.56
PASSIVE SELL 820.00 @ 830.69
PASSIVE BUY 1540.00 @ 830.63
PASSIVE BUY 1340.00 @ 830.67
AGGRESSIVE SELL 860.00 @ 830.67
PASSIVE SELL 2100.00 @ 830.81
AGGRESSIVE SELL 1100.00 @ 830.63
AGGRESSIVE SELL 2060.00 @ 830.62
CANCEL SELL 2100.00 @ 830.81
PASSIVE BUY 1620.00 @ 830.46
PASSIVE BUY 2060.00 @ 830.55
PASSIVE BUY 1740.00 @ 830.52
CANCEL BUY 2820.00 @ 830.58
CANCEL BUY 1700.00 @ 830.57
CANCEL BUY 2580.00 @ 830.53
CANCEL BUY 2460.00 @ 830.56
CANCEL BUY 1620.00 @ 830.46
CANCEL BUY 2060.00 @ 830.55
CANCEL BUY 1740.00 @ 830.52
PASSIVE BUY 1620.00 @ 830.55
PASSIVE SELL 1380.00 @ 830.63
CANCEL SELL 380.00 @ 830.79
AGGRESSIVE BUY 2860.00 @ 830.62
PASSIVE SELL 1380.00 @ 830.76
PASSIVE BUY 2060.00 @ 830.49
PASSIVE SELL 1100.00 @ 830.71
AGGRESSIVE SELL 820.00 @ 830.62
AGGRESSIVE SELL 1660.00 @ 830.57
CANCEL SELL 1380.00 @ 830.76
AGGRESSIVE SELL 980.00 @ 830.55
AGGRESSIVE SELL 540.00 @ 830.55
AGGRESSIVE BUY 1140.00 @ 830.62
PASSIVE SELL 2180.00 @ 830.67
AGGRESSIVE BUY 2860.00 @ 830.67
